üå± Seeding sample data...

1Ô∏è‚É£ Creating Sample 1: Waste Collection (Should VERIFY)
Error ingesting complaint: (400)
Reason: Bad Request
HTTP response headers: HTTPHeaderDict({'Date': 'Thu, 16 Oct 2025 09:37:14 GMT', 'Content-Type': 'application/json', 'Content-Length': '103', 'Connection': 'keep-alive', 'x-pinecone-request-latency-ms': '68', 'x-pinecone-request-id': '8327470665914556632', 'x-envoy-upstream-service-time': '40', 'server': 'envoy'})
HTTP response body: {"code":3,"message":"Vector dimension 512 does not match the dimension of the index 1536","details":[]}

Traceback (most recent call last):
  File "/app/backend/seed_sample_data.py", line 190, in <module>
    asyncio.run(seed_data())
  File "/usr/local/lib/python3.11/asyncio/runners.py", line 190, in run
    return runner.run(main)
           ^^^^^^^^^^^^^^^^
  File "/usr/local/lib/python3.11/asyncio/runners.py", line 118, in run
    return self._loop.run_until_complete(task)
           ^^^^^^^^^^^^^^^^^^^^^^^^^^^^^^^^^^^
  File "/usr/local/lib/python3.11/asyncio/base_events.py", line 654, in run_until_complete
    return future.result()
           ^^^^^^^^^^^^^^^
  File "/app/backend/seed_sample_data.py", line 70, in seed_data
    result1_complaint = await verification_pipeline.ingest_complaint(
                        ^^^^^^^^^^^^^^^^^^^^^^^^^^^^^^^^^^^^^^^^^^^^^
  File "/app/backend/verification_pipeline.py", line 47, in ingest_complaint
    self.pinecone.upsert_vector(
  File "/app/backend/pinecone_client.py", line 59, in upsert_vector
    index.upsert(vectors=[(vector_id, vector, metadata)], namespace=namespace)
  File "/root/.venv/lib/python3.11/site-packages/pinecone/utils/error_handling.py", line 30, in inner_func
    raise e from e
  File "/root/.venv/lib/python3.11/site-packages/pinecone/utils/error_handling.py", line 15, in inner_func
    return func(*args, **kwargs)
           ^^^^^^^^^^^^^^^^^^^^^
  File "/root/.venv/lib/python3.11/site-packages/pinecone/db_data/index.py", line 212, in upsert
    return self._upsert_batch(vectors, namespace, _check_type, **kwargs)
           ^^^^^^^^^^^^^^^^^^^^^^^^^^^^^^^^^^^^^^^^^^^^^^^^^^^^^^^^^^^^^
  File "/root/.venv/lib/python3.11/site-packages/pinecone/db_data/index.py", line 238, in _upsert_batch
    return self._vector_api.upsert_vectors(
           ^^^^^^^^^^^^^^^^^^^^^^^^^^^^^^^^
  File "/root/.venv/lib/python3.11/site-packages/pinecone/openapi_support/endpoint.py", line 102, in __call__
    return self.callable(self, *args, **kwargs)
           ^^^^^^^^^^^^^^^^^^^^^^^^^^^^^^^^^^^^
  File "/root/.venv/lib/python3.11/site-packages/pinecone/core/openapi/db_data/api/vector_operations_api.py", line 675, in __upsert_vectors
    return self.call_with_http_info(**kwargs)
           ^^^^^^^^^^^^^^^^^^^^^^^^^^^^^^^^^^
  File "/root/.venv/lib/python3.11/site-packages/pinecone/openapi_support/endpoint.py", line 134, in call_with_http_info
    return self.api_client.call_api(
           ^^^^^^^^^^^^^^^^^^^^^^^^^
  File "/root/.venv/lib/python3.11/site-packages/pinecone/openapi_support/api_client.py", line 306, in call_api
    return self.__call_api(
           ^^^^^^^^^^^^^^^^
  File "/root/.venv/lib/python3.11/site-packages/pinecone/openapi_support/api_client.py", line 182, in __call_api
    raise e
  File "/root/.venv/lib/python3.11/site-packages/pinecone/openapi_support/api_client.py", line 170, in __call_api
    response_data = self.request(
                    ^^^^^^^^^^^^^
  File "/root/.venv/lib/python3.11/site-packages/pinecone/openapi_support/api_client.py", line 386, in request
    return self.rest_client.POST(
           ^^^^^^^^^^^^^^^^^^^^^^
  File "/root/.venv/lib/python3.11/site-packages/pinecone/openapi_support/rest_utils.py", line 146, in POST
    return self.request(
           ^^^^^^^^^^^^^
  File "/root/.venv/lib/python3.11/site-packages/pinecone/openapi_support/rest_urllib3.py", line 267, in request
    return raise_exceptions_or_return(r)
           ^^^^^^^^^^^^^^^^^^^^^^^^^^^^^
  File "/root/.venv/lib/python3.11/site-packages/pinecone/openapi_support/rest_utils.py", line 49, in raise_exceptions_or_return
    raise PineconeApiException(http_resp=r)
pinecone.exceptions.exceptions.PineconeApiException: (400)
Reason: Bad Request
HTTP response headers: HTTPHeaderDict({'Date': 'Thu, 16 Oct 2025 09:37:14 GMT', 'Content-Type': 'application/json', 'Content-Length': '103', 'Connection': 'keep-alive', 'x-pinecone-request-latency-ms': '68', 'x-pinecone-request-id': '8327470665914556632', 'x-envoy-upstream-service-time': '40', 'server': 'envoy'})
HTTP response body: {"code":3,"message":"Vector dimension 512 does not match the dimension of the index 1536","details":[]}

